Workbook

Sheet hydrogen-transport
A1: Database | B1: hydrogen-transport
A3: Activity | B3: transport, hydrogen, gaseous, lorry, unspecified
A4: location | B4: GLO
A5: production amount | B5: 1
A6: reference product | B6: transport, hydrogen, gaseous, lorry, unspecified
A7: unit | B7: ton kilometer
A8: authors | B8: {"data entry": {"name": "Tobias", "email": "tobias.schliess@ier.uni-stuttgart.de"}, "data generator": {"name": "Tobias Schliess", "email": "tobias.schliess@ier.uni-stuttgart.de"}}
A9: comment | B9: LCI for gaseous hydrogen transport for 1 tkm. Storage tank taken from the hydrogen-distribution dataset. Lorry is market average. Boil-off losses are 0.5 % and 0.5 % during compression (Reuß et al. 2019)
A10: Exchanges
A11: name | B11: amount | C11: location | D11: unit | E11: categories | F11: type | G11: reference product | H11: uncertainty type | I11: comment
A12: =B6 -> transport, hydrogen, gaseous, lorry, unspecified | B12: =B5 -> 1 | C12: GLO | D12: ton kilometer | F12: production | G12: transport, hydrogen, gaseous, lorry, unspecified
A13: market for transport, freight, lorry, unspecified | B13: 1 | C13: RER | D13: ton kilometer | F13: technosphere | G13: transport, freight, lorry, diesel, unspecified | I13: this dataset is used as a proxy, so the lorry used uses the propulsion system chosen by the IAM scenario
A14: high pressure hydrogen storage tank | B14: =1*1000/540000 -> 0.0018518519 | C14: GLO | D14: kilogram | F14: technosphere | G14: high pressure hydrogen storage tank | I14: C. Wulf et al. / Journal of Cleaner Production 199 (2018) 431-443
A15: market for hydrogen, gaseous, low pressure | B15: =0.005 -> 0.005 | C15: RER | D15: kilogram | F15: technosphere | G15: hydrogen, gaseous, low pressure | I15: compensation for boil-off losses
A16: Hydrogen | B16: =0.005 -> 0.005 | D16: kilogram | E16: air | F16: biosphere | I16: boil-off losses to the atmosphere
A18: Activity | B18: transport, hydrogen, liquid, lorry, unspecified
A19: location | B19: GLO
A20: production amount | B20: 1
A21: reference product | B21: transport, hydrogen, liquid, lorry, unspecified
A22: unit | B22: ton kilometer
A23: authors | B23: {"data entry": {"name": "Tobias", "email": "tobias.schliess@ier.uni-stuttgart.de"}, "data generator": {"name": "Tobias Schliess", "email": "tobias.schliess@ier.uni-stuttgart.de"}}
A24: comment | B24: LCI for liquid hydrogen transport for 1 tkm. Storage tank taken from the hydrogen-distribution dataset. Lorry is market average. Boil-off losses are 3 % and 1.65 % during liquefaction (Reuß et al. 2019)
A25: Exchanges
A26: name | B26: amount | C26: location | D26: unit | E26: categories | F26: type | G26: reference product | H26: uncertainty type | I26: comment
A27: =B21 -> transport, hydrogen, liquid, lorry, unspecified | B27: =B20 -> 1 | C27: GLO | D27: ton kilometer | F27: production | G27: transport, hydrogen, liquid, lorry, unspecified
A28: market for transport, freight, lorry, unspecified | B28: 1 | C28: RER | D28: ton kilometer | F28: technosphere | G28: transport, freight, lorry, diesel, unspecified | I28: this dataset is used as a proxy, so the lorry used uses the propulsion system chosen by the IAM scenario
A29: high pressure hydrogen storage tank | B29: =1*1000/540000 -> 0.0018518519 | C29: GLO | D29: kilogram | F29: technosphere | G29: high pressure hydrogen storage tank | I29: C. Wulf et al. / Journal of Cleaner Production 199 (2018) 431-443
A30: market for hydrogen, gaseous, low pressure | B30: =0.01625 -> 0.01625 | C30: RER | D30: kilogram | F30: technosphere | G30: hydrogen, gaseous, low pressure | I30: compensation for boil-off losses
A31: Hydrogen | B31: =0.01625 -> 0.01625 | D31: kilogram | E31: air | F31: biosphere | I31: boil-off losses to the atmosphere
A33: Activity | B33: transport, freight, sea, tanker for liquefied ammonia, ammonia and mdo
A34: activity type | B34: ordinary transforming activity
A35: allocation | B35: equal
A36: authors | B36: {"data entry": {"name": "Tobias", "email": "tobias.schliess@ier.uni-stuttgart.de"}, "data generator": {"name": "Tobias Schliess", "email": "tobias.schliess@ier.uni-stuttgart.de"}}
A37: comment | B37: This dataset represents transporting 1 ton of liquid ammonia for 1 km using 95 % ammonia and 5 % marine gas oil (mgo) as fuel in a dual-fuel engine. Boil off gas (0.25% per day) are assumed to be reliquified, raising fuel consumption. The final product is hydrogen, gaseous, low pressure, which the electricity is needed for. Make-up hydrogen for losses is taken from the general market for hydrogen. The tanker chosen here is a 50,000 cbm vessel taken from IMO 2018, as a typical ship that size. The dataset is based on the transport, freight, sea, tanker for liquefied natural gas, heavy fuel oil dataset from ecoinvent v3. Auxiliary processes have therefore not been adapted.
A38: source | B38: ecoinvent 3.12 with additional assumptions - see comment
A39: location | B39: GLO
A40: reference product | B40: transport, freight, sea, tanker for liquefied ammonia, ammonia and mdo
A41: unit | B41: ton kilometer
A42: Exchanges
A43: name | B43: amount | C43: location | D43: unit | E43: categories | F43: type | G43: comment | H43: reference product
...

Sheet unused activities
A1: skip
A3: market for hydrogen, gaseous, low pressure | B3: 200.74 | C3: GLO | D3: kilogram | F3: technosphere | G3: make up hydrogen to account for losses along the supply chain: PSA recovery rate: 80 %, boil-off during loading and unloading: 0.037 % (source: de Kleijne et al 2024)
A4: market for hydrogen, gaseous, low pressure | B4: 1.0162 | C4: GLO | D4: kilogram | F4: technosphere | G4: market for hydrogen, gaseous, low pressure
A5: market for hydrogen, gaseous, low pressure | B5: 1.0162 | C5: GLO | D5: kilogram | F5: technosphere | G5: market for hydrogen, gaseous, low pressure
A6: market for hydrogen, gaseous, 25-30 bar | B6: 0.176 | C6: GLO | D6: kilogram | F6: technosphere | G6: market for hydrogen, gaseous, 25-30 bar
A7: market group for electricity, low voltage | B7: 0.6 | C7: GLO | D7: kilowatt hour | F7: technosphere | G7: electricity, low voltage | H7: As in ecoinvent dataset for hydrogen compression, from low to medium pressure
A8: market for hydrogen, gaseous, low pressure | B8: 0.35 | C8: RER | D8: kilogram | F8: technosphere | G8: hydrogen, gaseous, low pressure | H8: compensation for losses: Haber-Bosch process, Shipping and cracking (pressure swing adsorption)

Sheet parameters
A1: skip
B2: Fuels | C2: MDO | D2: NH3+MDO | E2: LH2 | F2: uni | G2: source
B3: LHV | C3: 11.861 | D3: 5.167 | F3: kWh/kg | G3: IMO 2018
B4: SEC in ship | C4: 0.02615 | D4: 0.02615 | F4: kWh/tkm input | G4: own calculations
B5: Main fuel input g | C5: 2.2051 | D5: 5.0619 | F5: g/tkm | G5: own calculations
B6: Main fuel input kWh | C6: 0.0262 | D6: 0.0262 | F6: kWh/tkm input | G6: own calculations
B7: Pilot fuel input g | C7: 0.1147 | D7: 0.1147 | F7: g/tkm | G7: own calculations
B8: Pilot fuel input tkm | C8: 0.0014 | D8: 0.0014 | F8: kWh/tkm input | G8: own calculations
B9: Share of days at SECA | C9: =(22/229) -> 0.096069869 | D9: =(22/229) -> 0.096069869 | F9: % | G9: IMO 2018
B10: Urea solution input | C10: 5.9 | D10: 5.9 | F10: g/kWh fuel combusted | G10: Sphera 2024
B11: EF CO2 NH3 | C11: 0 | D11: 0 | F11: g/kWh fuel combusted
B12: EF N2O Tier II NH3 | C12: 0 | D12: 0.2 | F12: g/kWh fuel combusted | G12: Sphera 2024
B13: EF N2O Tier III NH3 | C13: 0 | D13: 0.5 | F13: g/kWh fuel combusted | G13: Sphera 2024
B14: EF CH4 NH3 | C14: 0 | D14: 0 | F14: g/kWh fuel combusted
B15: EF NH3 Tier II NH3 | C15: 0 | D15: 0.1 | F15: g/kWh fuel combusted | G15: Sphera 2024
B16: EF NH3 Tier III NH3 | C16: 0 | D16: 2 | F16: g/kWh fuel combusted | G16: Sphera 2024
B17: EF Nox Tier II NH3 | C17: 0 | D17: 1.7 | F17: g/kWh fuel combusted | G17: Sphera 2024
B18: EF Nox Tier III NH3 | C18: 0 | D18: 6.31 | F18: g/kWh fuel combusted | G18: Sphera 2024
B19: EF Sox NH3 | C19: 0 | D19: 0 | F19: g/kWh fuel combusted
B20: EF PM2.5 NH3 | C20: 0 | D20: 0 | F20: g/kWh fuel combusted
B21: EF NMVOC NH3 | C21: 0 | D21: 0 | F21: g/kWh fuel combusted
B22: EF CO2 MDO | C22: 249.12 | D22: 249.12 | F22: g/kWh fuel combusted | G22: IMO 2018
B23: EF N2O MDO | C23: 0.0136 | D23: 0.0136 | F23: g/kWh fuel combusted | G23: IMO 2018
B24: EF CO MDO | C24: 0.2 | D24: 0.2 | F24: g/kWh fuel combusted | G24: Wei et al 2025
B25: EF CH4 MDO | C25: 0.01 | D25: 0.01 | F25: g/kWh fuel combusted | G25: IMO 2018
B26: EF NH3 MDO | C26: 0 | D26: 0 | F26: g/kWh fuel combusted | G26: Wei et al 2025
B27: EF Nox Tier II MDO | C27: 3.4 | D27: 3.4 | F27: g/kWh fuel combusted | G27: IMO 2018
B28: EF Nox Tier III MDO | C28: 14.4 | D28: 14.4 | F28: g/kWh fuel combusted | G28: IMO 2018
B29: EF Sox MDO | C29: 0.09 | D29: 0.09 | F29: g/kWh fuel combusted | G29: Wei et al 2025
B30: EF PM2.5 MDO | C30: 0.031 | D30: 0.031 | F30: g/kWh fuel combusted | G30: Wei et al 2025
B31: EF PM10 MDO | C31: 0.003 | D31: 0.003 | F31: g/kWh fuel combusted | G31: Wei et al 2025
B32: EF NMVOC MDO | C32: 0.1 | D32: 0.1 | F32: g/kWh fuel combusted | G32: Wei et al 2025
B34: Cargo | C34: NH3 | D34: NH3
